Traceback (most recent call last):
  File "/home/mmann1123/anaconda3/envs/pygisbook/lib/python3.7/site-packages/jupyter_cache/executors/utils.py", line 56, in single_nb_execution
    record_timing=False,
  File "/home/mmann1123/anaconda3/envs/pygisbook/lib/python3.7/site-packages/nbclient/client.py", line 1112, in execute
    return NotebookClient(nb=nb, resources=resources, km=km, **kwargs).execute()
  File "/home/mmann1123/anaconda3/envs/pygisbook/lib/python3.7/site-packages/nbclient/util.py", line 74, in wrapped
    return just_run(coro(*args, **kwargs))
  File "/home/mmann1123/anaconda3/envs/pygisbook/lib/python3.7/site-packages/nbclient/util.py", line 53, in just_run
    return loop.run_until_complete(coro)
  File "/home/mmann1123/anaconda3/envs/pygisbook/lib/python3.7/asyncio/base_events.py", line 587, in run_until_complete
    return future.result()
  File "/home/mmann1123/anaconda3/envs/pygisbook/lib/python3.7/site-packages/nbclient/client.py", line 554, in async_execute
    cell, index, execution_count=self.code_cells_executed + 1
  File "/home/mmann1123/anaconda3/envs/pygisbook/lib/python3.7/site-packages/nbclient/client.py", line 857, in async_execute_cell
    self._check_raise_for_error(cell, exec_reply)
  File "/home/mmann1123/anaconda3/envs/pygisbook/lib/python3.7/site-packages/nbclient/client.py", line 760, in _check_raise_for_error
    raise CellExecutionError.from_cell_and_msg(cell, exec_reply_content)
nbclient.exceptions.CellExecutionError: An error occurred while executing the following cell:
------------------
import geowombat as gw
import matplotlib.pyplot as plt

fig, ax = plt.subplots(dpi=200)

# tell gw to read a blue green red
with gw.config.update(sensor="bgr"):
    with gw.open("../data/LC08_L1TP_224078_20200518_20200518_01_RT.TIF") as src:
        
        # see that bands names, blue green red are assigned
        print(src.band)

        # remove 0 value, rearrange band order 
        temp = src.where(src != 0).sel(band=["red", "green", "blue"])

        # plot
        temp.gw.imshow(robust=True, ax=ax)

        #save to file
        temp.gw.to_raster(
            "../temp/LS_scaled_20200518.tif", verbose=0, n_workers=4, overwrite=True
        )
------------------

[0;31m---------------------------------------------------------------------------[0m
[0;31mModuleNotFoundError[0m                       Traceback (most recent call last)
[0;32m<ipython-input-15-6b3940a41b00>[0m in [0;36m<module>[0;34m[0m
[0;32m----> 1[0;31m [0;32mimport[0m [0mgeowombat[0m [0;32mas[0m [0mgw[0m[0;34m[0m[0;34m[0m[0m
[0m[1;32m      2[0m [0;32mimport[0m [0mmatplotlib[0m[0;34m.[0m[0mpyplot[0m [0;32mas[0m [0mplt[0m[0;34m[0m[0;34m[0m[0m
[1;32m      3[0m [0;34m[0m[0m
[1;32m      4[0m [0mfig[0m[0;34m,[0m [0max[0m [0;34m=[0m [0mplt[0m[0;34m.[0m[0msubplots[0m[0;34m([0m[0mdpi[0m[0;34m=[0m[0;36m200[0m[0;34m)[0m[0;34m[0m[0;34m[0m[0m
[1;32m      5[0m [0;34m[0m[0m

[0;31mModuleNotFoundError[0m: No module named 'geowombat'
ModuleNotFoundError: No module named 'geowombat'

