Traceback (most recent call last):
  File "/home/mmann1123/anaconda3/envs/pygisbook/lib/python3.7/site-packages/jupyter_cache/executors/utils.py", line 56, in single_nb_execution
    record_timing=False,
  File "/home/mmann1123/anaconda3/envs/pygisbook/lib/python3.7/site-packages/nbclient/client.py", line 1112, in execute
    return NotebookClient(nb=nb, resources=resources, km=km, **kwargs).execute()
  File "/home/mmann1123/anaconda3/envs/pygisbook/lib/python3.7/site-packages/nbclient/util.py", line 74, in wrapped
    return just_run(coro(*args, **kwargs))
  File "/home/mmann1123/anaconda3/envs/pygisbook/lib/python3.7/site-packages/nbclient/util.py", line 53, in just_run
    return loop.run_until_complete(coro)
  File "/home/mmann1123/anaconda3/envs/pygisbook/lib/python3.7/asyncio/base_events.py", line 587, in run_until_complete
    return future.result()
  File "/home/mmann1123/anaconda3/envs/pygisbook/lib/python3.7/site-packages/nbclient/client.py", line 554, in async_execute
    cell, index, execution_count=self.code_cells_executed + 1
  File "/home/mmann1123/anaconda3/envs/pygisbook/lib/python3.7/site-packages/nbclient/client.py", line 857, in async_execute_cell
    self._check_raise_for_error(cell, exec_reply)
  File "/home/mmann1123/anaconda3/envs/pygisbook/lib/python3.7/site-packages/nbclient/client.py", line 760, in _check_raise_for_error
    raise CellExecutionError.from_cell_and_msg(cell, exec_reply_content)
nbclient.exceptions.CellExecutionError: An error occurred while executing the following cell:
------------------
# read the point data in 
df = pd.read_csv(path_to_csv)

# Create a geodataframe from the data using from_epsg to assign WGS84 coordinate reference system
points= gpd.GeoDataFrame(df, geometry=gpd.points_from_xy(x=df.lon, y=df.lat), crs = from_epsg(4326))
points
------------------

[0;31m---------------------------------------------------------------------------[0m
[0;31mNameError[0m                                 Traceback (most recent call last)
[0;32m<ipython-input-5-186bad8aea46>[0m in [0;36m<module>[0;34m[0m
[1;32m      3[0m [0;34m[0m[0m
[1;32m      4[0m [0;31m# Create a geodataframe from the data using from_epsg to assign WGS84 coordinate reference system[0m[0;34m[0m[0;34m[0m[0;34m[0m[0m
[0;32m----> 5[0;31m [0mpoints[0m[0;34m=[0m [0mgpd[0m[0;34m.[0m[0mGeoDataFrame[0m[0;34m([0m[0mdf[0m[0;34m,[0m [0mgeometry[0m[0;34m=[0m[0mgpd[0m[0;34m.[0m[0mpoints_from_xy[0m[0;34m([0m[0mx[0m[0;34m=[0m[0mdf[0m[0;34m.[0m[0mlon[0m[0;34m,[0m [0my[0m[0;34m=[0m[0mdf[0m[0;34m.[0m[0mlat[0m[0;34m)[0m[0;34m,[0m [0mcrs[0m [0;34m=[0m [0mfrom_epsg[0m[0;34m([0m[0;36m4326[0m[0;34m)[0m[0;34m)[0m[0;34m[0m[0;34m[0m[0m
[0m[1;32m      6[0m [0mpoints[0m[0;34m[0m[0;34m[0m[0m

[0;31mNameError[0m: name 'from_epsg' is not defined
NameError: name 'from_epsg' is not defined

