Traceback (most recent call last):
  File "/home/mmann1123/anaconda3/envs/pygisbookgw/lib/python3.7/site-packages/jupyter_cache/executors/utils.py", line 56, in single_nb_execution
    record_timing=False,
  File "/home/mmann1123/anaconda3/envs/pygisbookgw/lib/python3.7/site-packages/nbclient/client.py", line 1112, in execute
    return NotebookClient(nb=nb, resources=resources, km=km, **kwargs).execute()
  File "/home/mmann1123/anaconda3/envs/pygisbookgw/lib/python3.7/site-packages/nbclient/util.py", line 74, in wrapped
    return just_run(coro(*args, **kwargs))
  File "/home/mmann1123/anaconda3/envs/pygisbookgw/lib/python3.7/site-packages/nbclient/util.py", line 53, in just_run
    return loop.run_until_complete(coro)
  File "/home/mmann1123/anaconda3/envs/pygisbookgw/lib/python3.7/asyncio/base_events.py", line 587, in run_until_complete
    return future.result()
  File "/home/mmann1123/anaconda3/envs/pygisbookgw/lib/python3.7/site-packages/nbclient/client.py", line 554, in async_execute
    cell, index, execution_count=self.code_cells_executed + 1
  File "/home/mmann1123/anaconda3/envs/pygisbookgw/lib/python3.7/site-packages/nbclient/client.py", line 857, in async_execute_cell
    self._check_raise_for_error(cell, exec_reply)
  File "/home/mmann1123/anaconda3/envs/pygisbookgw/lib/python3.7/site-packages/nbclient/client.py", line 760, in _check_raise_for_error
    raise CellExecutionError.from_cell_and_msg(cell, exec_reply_content)
nbclient.exceptions.CellExecutionError: An error occurred while executing the following cell:
------------------
# create a numeric unique value for each row
vector['id'] = range(0,len(vector))

# create tuples of geometry, value pairs, where value is the attribute value you want to burn
geom_value = ((geom,value) for geom, value in zip(vector.geometry, vector['id']))

# Rasterize vector using the shape and transform of the raster
rasterized = features.rasterize(geom_value,
                                out_shape = raster.shape,
                                transform = raster.transform,
                                all_touched = True,
                                fill = -5,   # background value
                                merge_alg = MergeAlg.replace,
                                dtype = np.int16)

# Plot raster
fig, ax = plt.subplots(1, figsize = (10, 10))
show(rasterized, ax = ax)
plt.gca().invert_yaxis()
------------------

[0;31m---------------------------------------------------------------------------[0m
[0;31mNameError[0m                                 Traceback (most recent call last)
[0;32m<ipython-input-4-c729bccc3e19>[0m in [0;36m<module>[0;34m[0m
[1;32m     12[0m                                 [0mfill[0m [0;34m=[0m [0;34m-[0m[0;36m5[0m[0;34m,[0m   [0;31m# background value[0m[0;34m[0m[0;34m[0m[0m
[1;32m     13[0m                                 [0mmerge_alg[0m [0;34m=[0m [0mMergeAlg[0m[0;34m.[0m[0mreplace[0m[0;34m,[0m[0;34m[0m[0;34m[0m[0m
[0;32m---> 14[0;31m                                 dtype = np.int16)
[0m[1;32m     15[0m [0;34m[0m[0m
[1;32m     16[0m [0;31m# Plot raster[0m[0;34m[0m[0;34m[0m[0;34m[0m[0m

[0;31mNameError[0m: name 'np' is not defined
NameError: name 'np' is not defined

