Traceback (most recent call last):
  File "/home/mmann1123/anaconda3/envs/pygisbookgw/lib/python3.7/site-packages/jupyter_cache/executors/utils.py", line 56, in single_nb_execution
    record_timing=False,
  File "/home/mmann1123/anaconda3/envs/pygisbookgw/lib/python3.7/site-packages/nbclient/client.py", line 1112, in execute
    return NotebookClient(nb=nb, resources=resources, km=km, **kwargs).execute()
  File "/home/mmann1123/anaconda3/envs/pygisbookgw/lib/python3.7/site-packages/nbclient/util.py", line 74, in wrapped
    return just_run(coro(*args, **kwargs))
  File "/home/mmann1123/anaconda3/envs/pygisbookgw/lib/python3.7/site-packages/nbclient/util.py", line 53, in just_run
    return loop.run_until_complete(coro)
  File "/home/mmann1123/anaconda3/envs/pygisbookgw/lib/python3.7/asyncio/base_events.py", line 587, in run_until_complete
    return future.result()
  File "/home/mmann1123/anaconda3/envs/pygisbookgw/lib/python3.7/site-packages/nbclient/client.py", line 554, in async_execute
    cell, index, execution_count=self.code_cells_executed + 1
  File "/home/mmann1123/anaconda3/envs/pygisbookgw/lib/python3.7/site-packages/nbclient/client.py", line 857, in async_execute_cell
    self._check_raise_for_error(cell, exec_reply)
  File "/home/mmann1123/anaconda3/envs/pygisbookgw/lib/python3.7/site-packages/nbclient/client.py", line 760, in _check_raise_for_error
    raise CellExecutionError.from_cell_and_msg(cell, exec_reply_content)
nbclient.exceptions.CellExecutionError: An error occurred while executing the following cell:
------------------
# Export raster
export_kde_raster(Z = Z_sk, XX = XX_sk, YY = YY_sk,
                  min_x = min_x_sk, max_x = max_x_sk, min_y = min_y_sk, max_y = max_y_sk,
                  proj = proj_wgs, filename = "../_static/e_vector_shapefiles/outputs/bay-area-wells_kde_sklearn.tif")
------------------

[0;31m---------------------------------------------------------------------------[0m
[0;31mCPLE_OpenFailedError[0m                      Traceback (most recent call last)
[0;32mrasterio/_io.pyx[0m in [0;36mrasterio._io.DatasetWriterBase.__init__[0;34m()[0m

[0;32mrasterio/_err.pyx[0m in [0;36mrasterio._err.exc_wrap_pointer[0;34m()[0m

[0;31mCPLE_OpenFailedError[0m: Attempt to create new tiff file '../_static/e_vector_shapefiles/outputs/bay-area-wells_kde_sklearn.tif' failed: No such file or directory

During handling of the above exception, another exception occurred:

[0;31mRasterioIOError[0m                           Traceback (most recent call last)
[0;32m<ipython-input-17-565335b6bb2a>[0m in [0;36m<module>[0;34m[0m
[1;32m      2[0m export_kde_raster(Z = Z_sk, XX = XX_sk, YY = YY_sk,
[1;32m      3[0m                   [0mmin_x[0m [0;34m=[0m [0mmin_x_sk[0m[0;34m,[0m [0mmax_x[0m [0;34m=[0m [0mmax_x_sk[0m[0;34m,[0m [0mmin_y[0m [0;34m=[0m [0mmin_y_sk[0m[0;34m,[0m [0mmax_y[0m [0;34m=[0m [0mmax_y_sk[0m[0;34m,[0m[0;34m[0m[0;34m[0m[0m
[0;32m----> 4[0;31m                   proj = proj_wgs, filename = "../_static/e_vector_shapefiles/outputs/bay-area-wells_kde_sklearn.tif")
[0m
[0;32m<ipython-input-16-79b64e52391d>[0m in [0;36mexport_kde_raster[0;34m(Z, XX, YY, min_x, max_x, min_y, max_y, proj, filename)[0m
[1;32m     22[0m             [0mdtype[0m [0;34m=[0m [0mZ_export[0m[0;34m.[0m[0mdtype[0m[0;34m,[0m[0;34m[0m[0;34m[0m[0m
[1;32m     23[0m             [0mcrs[0m [0;34m=[0m [0mproj[0m[0;34m,[0m[0;34m[0m[0;34m[0m[0m
[0;32m---> 24[0;31m             [0mtransform[0m [0;34m=[0m [0mtransform[0m[0;34m,[0m[0;34m[0m[0;34m[0m[0m
[0m[1;32m     25[0m     ) as new_dataset:
[1;32m     26[0m             [0mnew_dataset[0m[0;34m.[0m[0mwrite[0m[0;34m([0m[0mZ_export[0m[0;34m,[0m [0;36m1[0m[0;34m)[0m[0;34m[0m[0;34m[0m[0m

[0;32m~/anaconda3/envs/pygisbookgw/lib/python3.7/site-packages/rasterio/env.py[0m in [0;36mwrapper[0;34m(*args, **kwds)[0m
[1;32m    433[0m [0;34m[0m[0m
[1;32m    434[0m         [0;32mwith[0m [0menv_ctor[0m[0;34m([0m[0msession[0m[0;34m=[0m[0msession[0m[0;34m)[0m[0;34m:[0m[0;34m[0m[0;34m[0m[0m
[0;32m--> 435[0;31m             [0;32mreturn[0m [0mf[0m[0;34m([0m[0;34m*[0m[0margs[0m[0;34m,[0m [0;34m**[0m[0mkwds[0m[0;34m)[0m[0;34m[0m[0;34m[0m[0m
[0m[1;32m    436[0m [0;34m[0m[0m
[1;32m    437[0m     [0;32mreturn[0m [0mwrapper[0m[0;34m[0m[0;34m[0m[0m

[0;32m~/anaconda3/envs/pygisbookgw/lib/python3.7/site-packages/rasterio/__init__.py[0m in [0;36mopen[0;34m(fp, mode, driver, width, height, count, crs, transform, dtype, nodata, sharing, **kwargs)[0m
[1;32m    234[0m                            [0mdtype[0m[0;34m=[0m[0mdtype[0m[0;34m,[0m [0mnodata[0m[0;34m=[0m[0mnodata[0m[0;34m,[0m[0;34m[0m[0;34m[0m[0m
[1;32m    235[0m                            [0msharing[0m[0;34m=[0m[0msharing[0m[0;34m,[0m[0;34m[0m[0;34m[0m[0m
[0;32m--> 236[0;31m                            **kwargs)
[0m[1;32m    237[0m             [0;32melse[0m[0;34m:[0m[0;34m[0m[0;34m[0m[0m
[1;32m    238[0m                 raise DriverCapabilityError(

[0;32mrasterio/_io.pyx[0m in [0;36mrasterio._io.DatasetWriterBase.__init__[0;34m()[0m

[0;31mRasterioIOError[0m: Attempt to create new tiff file '../_static/e_vector_shapefiles/outputs/bay-area-wells_kde_sklearn.tif' failed: No such file or directory
RasterioIOError: Attempt to create new tiff file '../_static/e_vector_shapefiles/outputs/bay-area-wells_kde_sklearn.tif' failed: No such file or directory

