Traceback (most recent call last):
  File "/mnt/space/miniconda3/envs/pygisbook/lib/python3.9/site-packages/jupyter_cache/executors/utils.py", line 51, in single_nb_execution
    executenb(
  File "/mnt/space/miniconda3/envs/pygisbook/lib/python3.9/site-packages/nbclient/client.py", line 1204, in execute
    return NotebookClient(nb=nb, resources=resources, km=km, **kwargs).execute()
  File "/mnt/space/miniconda3/envs/pygisbook/lib/python3.9/site-packages/nbclient/util.py", line 84, in wrapped
    return just_run(coro(*args, **kwargs))
  File "/mnt/space/miniconda3/envs/pygisbook/lib/python3.9/site-packages/nbclient/util.py", line 62, in just_run
    return loop.run_until_complete(coro)
  File "/mnt/space/miniconda3/envs/pygisbook/lib/python3.9/asyncio/base_events.py", line 647, in run_until_complete
    return future.result()
  File "/mnt/space/miniconda3/envs/pygisbook/lib/python3.9/site-packages/nbclient/client.py", line 663, in async_execute
    await self.async_execute_cell(
  File "/mnt/space/miniconda3/envs/pygisbook/lib/python3.9/site-packages/nbclient/client.py", line 965, in async_execute_cell
    await self._check_raise_for_error(cell, cell_index, exec_reply)
  File "/mnt/space/miniconda3/envs/pygisbook/lib/python3.9/site-packages/nbclient/client.py", line 862, in _check_raise_for_error
    raise CellExecutionError.from_cell_and_msg(cell, exec_reply_content)
nbclient.exceptions.CellExecutionError: An error occurred while executing the following cell:
------------------
plot('union')
------------------

[0;31m---------------------------------------------------------------------------[0m
[0;31mAttributeError[0m                            Traceback (most recent call last)
Cell [0;32mIn [4], line 1[0m
[0;32m----> 1[0m plot([38;5;124m'[39m[38;5;124munion[39m[38;5;124m'[39m)

Cell [0;32mIn [3], line 16[0m, in [0;36mplot[0;34m(bounds_by, ref_image, cmap)[0m
[1;32m     14[0m srca[38;5;241m.[39mgw[38;5;241m.[39mchunk_grid[38;5;241m.[39mplot(color[38;5;241m=[39m[38;5;124m'[39m[38;5;124mnone[39m[38;5;124m'[39m, edgecolor[38;5;241m=[39m[38;5;124m'[39m[38;5;124mk[39m[38;5;124m'[39m, ls[38;5;241m=[39m[38;5;124m'[39m[38;5;124m-[39m[38;5;124m'[39m, lw[38;5;241m=[39m[38;5;241m0.5[39m, ax[38;5;241m=[39max)
[1;32m     15[0m [38;5;66;03m# Plot the image footprints[39;00m
[0;32m---> 16[0m [43msrca[49m[38;5;241;43m.[39;49m[43mgw[49m[38;5;241;43m.[39;49m[43mfootprint_grid[49m[38;5;241m.[39mplot(color[38;5;241m=[39m[38;5;124m'[39m[38;5;124mnone[39m[38;5;124m'[39m, edgecolor[38;5;241m=[39m[38;5;124m'[39m[38;5;124morange[39m[38;5;124m'[39m, lw[38;5;241m=[39m[38;5;241m2[39m, ax[38;5;241m=[39max)
[1;32m     17[0m [38;5;66;03m# Label the image footprints[39;00m
[1;32m     18[0m [38;5;28;01mfor[39;00m row [38;5;129;01min[39;00m srca[38;5;241m.[39mgw[38;5;241m.[39mfootprint_grid[38;5;241m.[39mitertuples(index[38;5;241m=[39m[38;5;28;01mFalse[39;00m):

File [0;32m/mnt/space/miniconda3/envs/pygisbook/lib/python3.9/site-packages/geowombat/core/properties.py:828[0m, in [0;36mDataProperties.footprint_grid[0;34m(self)[0m
[1;32m    826[0m [38;5;124;03m"""Get the image footprint grid."""[39;00m
[1;32m    827[0m [38;5;28;01mif[39;00m [38;5;129;01mnot[39;00m [38;5;28mhasattr[39m([38;5;28mself[39m[38;5;241m.[39m_obj, [38;5;124m'[39m[38;5;124m_filenames[39m[38;5;124m'[39m):
[0;32m--> 828[0m     [38;5;28;01mraise[39;00m [38;5;167;01mAttributeError[39;00m(
[1;32m    829[0m         [38;5;124m"[39m[38;5;124mThe DataArray object does not have a [39m[38;5;124m'[39m[38;5;124mfilenames[39m[38;5;124m'[39m[38;5;124m attribute.[39m[38;5;124m"[39m
[1;32m    830[0m     )
[1;32m    831[0m [38;5;28;01mimport[39;00m [38;5;21;01mgeowombat[39;00m [38;5;28;01mas[39;00m [38;5;21;01mgw_[39;00m
[1;32m    833[0m [38;5;28;01mif[39;00m [38;5;28mhasattr[39m([38;5;28mself[39m[38;5;241m.[39m_obj, [38;5;124m'[39m[38;5;124mgeometries[39m[38;5;124m'[39m):

[0;31mAttributeError[0m: The DataArray object does not have a 'filenames' attribute.
AttributeError: The DataArray object does not have a 'filenames' attribute.

