Traceback (most recent call last):
  File "/home/mmann1123/anaconda3/envs/pygisbook/lib/python3.7/site-packages/jupyter_cache/executors/utils.py", line 56, in single_nb_execution
    record_timing=False,
  File "/home/mmann1123/anaconda3/envs/pygisbook/lib/python3.7/site-packages/nbclient/client.py", line 1112, in execute
    return NotebookClient(nb=nb, resources=resources, km=km, **kwargs).execute()
  File "/home/mmann1123/anaconda3/envs/pygisbook/lib/python3.7/site-packages/nbclient/util.py", line 74, in wrapped
    return just_run(coro(*args, **kwargs))
  File "/home/mmann1123/anaconda3/envs/pygisbook/lib/python3.7/site-packages/nbclient/util.py", line 53, in just_run
    return loop.run_until_complete(coro)
  File "/home/mmann1123/anaconda3/envs/pygisbook/lib/python3.7/asyncio/base_events.py", line 587, in run_until_complete
    return future.result()
  File "/home/mmann1123/anaconda3/envs/pygisbook/lib/python3.7/site-packages/nbclient/client.py", line 554, in async_execute
    cell, index, execution_count=self.code_cells_executed + 1
  File "/home/mmann1123/anaconda3/envs/pygisbook/lib/python3.7/site-packages/nbclient/client.py", line 857, in async_execute_cell
    self._check_raise_for_error(cell, exec_reply)
  File "/home/mmann1123/anaconda3/envs/pygisbook/lib/python3.7/site-packages/nbclient/client.py", line 760, in _check_raise_for_error
    raise CellExecutionError.from_cell_and_msg(cell, exec_reply_content)
nbclient.exceptions.CellExecutionError: An error occurred while executing the following cell:
------------------
import matplotlib.pyplot as plt
plt.style.use('bmh') # better for plotting geometries vs general plots.

world = geopandas.read_file(geopandas.datasets.get_path('naturalearth_cities'))
northern_world = world.iloc[ 0:4 ]    
plot(northern_world,figsize=(10, 5))  
plt.show()
------------------

[0;31m---------------------------------------------------------------------------[0m
[0;31mNameError[0m                                 Traceback (most recent call last)
[0;32m<ipython-input-12-32056e091d1b>[0m in [0;36m<module>[0;34m[0m
[1;32m      4[0m [0mworld[0m [0;34m=[0m [0mgeopandas[0m[0;34m.[0m[0mread_file[0m[0;34m([0m[0mgeopandas[0m[0;34m.[0m[0mdatasets[0m[0;34m.[0m[0mget_path[0m[0;34m([0m[0;34m'naturalearth_cities'[0m[0;34m)[0m[0;34m)[0m[0;34m[0m[0;34m[0m[0m
[1;32m      5[0m [0mnorthern_world[0m [0;34m=[0m [0mworld[0m[0;34m.[0m[0miloc[0m[0;34m[[0m [0;36m0[0m[0;34m:[0m[0;36m4[0m [0;34m][0m[0;34m[0m[0;34m[0m[0m
[0;32m----> 6[0;31m [0mplot[0m[0;34m([0m[0mnorthern_world[0m[0;34m,[0m[0mfigsize[0m[0;34m=[0m[0;34m([0m[0;36m10[0m[0;34m,[0m [0;36m5[0m[0;34m)[0m[0;34m)[0m[0;34m[0m[0;34m[0m[0m
[0m[1;32m      7[0m [0mplt[0m[0;34m.[0m[0mshow[0m[0;34m([0m[0;34m)[0m[0;34m[0m[0;34m[0m[0m

[0;31mNameError[0m: name 'plot' is not defined
NameError: name 'plot' is not defined

