Traceback (most recent call last):
  File "/home/mmann1123/anaconda3/envs/pygisbookgw/lib/python3.7/site-packages/jupyter_cache/executors/utils.py", line 56, in single_nb_execution
    record_timing=False,
  File "/home/mmann1123/anaconda3/envs/pygisbookgw/lib/python3.7/site-packages/nbclient/client.py", line 1112, in execute
    return NotebookClient(nb=nb, resources=resources, km=km, **kwargs).execute()
  File "/home/mmann1123/anaconda3/envs/pygisbookgw/lib/python3.7/site-packages/nbclient/util.py", line 74, in wrapped
    return just_run(coro(*args, **kwargs))
  File "/home/mmann1123/anaconda3/envs/pygisbookgw/lib/python3.7/site-packages/nbclient/util.py", line 53, in just_run
    return loop.run_until_complete(coro)
  File "/home/mmann1123/anaconda3/envs/pygisbookgw/lib/python3.7/asyncio/base_events.py", line 587, in run_until_complete
    return future.result()
  File "/home/mmann1123/anaconda3/envs/pygisbookgw/lib/python3.7/site-packages/nbclient/client.py", line 554, in async_execute
    cell, index, execution_count=self.code_cells_executed + 1
  File "/home/mmann1123/anaconda3/envs/pygisbookgw/lib/python3.7/site-packages/nbclient/client.py", line 857, in async_execute_cell
    self._check_raise_for_error(cell, exec_reply)
  File "/home/mmann1123/anaconda3/envs/pygisbookgw/lib/python3.7/site-packages/nbclient/client.py", line 760, in _check_raise_for_error
    raise CellExecutionError.from_cell_and_msg(cell, exec_reply_content)
nbclient.exceptions.CellExecutionError: An error occurred while executing the following cell:
------------------
from rasterio.transform import Affine
import rasterio as rio

res = (x[-1] - x[0]) / 240.0
transform = Affine.translation(x[0] - res / 2, y[0] - res / 2) * Affine.scale(res, res)

# open in 'write' mode, unpack profile info to dst
with rio.open(
   "../temp/new_raster.tif",
   "w",
   driver="GTiff",       # output file type
   height=Z.shape[0],    # shape of array
   width=Z.shape[1],
   dtype=Z.dtype,        # output datatype
   crs="+proj=latlong",  # CRS
   transform=transform,  # location and resolution of upper left cell
) as dst:

   # check for multiband
   if len(Z.shape) == 3:
       # write each band individually
       for band in range(len(Z)):
           # write data, band # (starting from 1)
           dst.write(Z[band], band + 1)
   # write single band
   else:
       dst.write(Z, 1)
------------------

[0;31m---------------------------------------------------------------------------[0m
[0;31mTypeError[0m                                 Traceback (most recent call last)
[0;32mrasterio/_io.pyx[0m in [0;36mrasterio._io.DatasetWriterBase.__init__[0;34m()[0m

[0;31mTypeError[0m: int() argument must be a string, a bytes-like object or a number, not 'NoneType'

During handling of the above exception, another exception occurred:

[0;31mTypeError[0m                                 Traceback (most recent call last)
[0;32m<ipython-input-4-da7f92c0ee3c>[0m in [0;36m<module>[0;34m[0m
[1;32m     14[0m    [0mdtype[0m[0;34m=[0m[0mZ[0m[0;34m.[0m[0mdtype[0m[0;34m,[0m        [0;31m# output datatype[0m[0;34m[0m[0;34m[0m[0m
[1;32m     15[0m    [0mcrs[0m[0;34m=[0m[0;34m"+proj=latlong"[0m[0;34m,[0m  [0;31m# CRS[0m[0;34m[0m[0;34m[0m[0m
[0;32m---> 16[0;31m    [0mtransform[0m[0;34m=[0m[0mtransform[0m[0;34m,[0m  [0;31m# location and resolution of upper left cell[0m[0;34m[0m[0;34m[0m[0m
[0m[1;32m     17[0m ) as dst:
[1;32m     18[0m [0;34m[0m[0m

[0;32m~/anaconda3/envs/pygisbookgw/lib/python3.7/site-packages/rasterio/env.py[0m in [0;36mwrapper[0;34m(*args, **kwds)[0m
[1;32m    433[0m [0;34m[0m[0m
[1;32m    434[0m         [0;32mwith[0m [0menv_ctor[0m[0;34m([0m[0msession[0m[0;34m=[0m[0msession[0m[0;34m)[0m[0;34m:[0m[0;34m[0m[0;34m[0m[0m
[0;32m--> 435[0;31m             [0;32mreturn[0m [0mf[0m[0;34m([0m[0;34m*[0m[0margs[0m[0;34m,[0m [0;34m**[0m[0mkwds[0m[0;34m)[0m[0;34m[0m[0;34m[0m[0m
[0m[1;32m    436[0m [0;34m[0m[0m
[1;32m    437[0m     [0;32mreturn[0m [0mwrapper[0m[0;34m[0m[0;34m[0m[0m

[0;32m~/anaconda3/envs/pygisbookgw/lib/python3.7/site-packages/rasterio/__init__.py[0m in [0;36mopen[0;34m(fp, mode, driver, width, height, count, crs, transform, dtype, nodata, sharing, **kwargs)[0m
[1;32m    234[0m                            [0mdtype[0m[0;34m=[0m[0mdtype[0m[0;34m,[0m [0mnodata[0m[0;34m=[0m[0mnodata[0m[0;34m,[0m[0;34m[0m[0;34m[0m[0m
[1;32m    235[0m                            [0msharing[0m[0;34m=[0m[0msharing[0m[0;34m,[0m[0;34m[0m[0;34m[0m[0m
[0;32m--> 236[0;31m                            **kwargs)
[0m[1;32m    237[0m             [0;32melse[0m[0;34m:[0m[0;34m[0m[0;34m[0m[0m
[1;32m    238[0m                 raise DriverCapabilityError(

[0;32mrasterio/_io.pyx[0m in [0;36mrasterio._io.DatasetWriterBase.__init__[0;34m()[0m

[0;31mTypeError[0m: Integer band count is required.
TypeError: Integer band count is required.

