Traceback (most recent call last):
  File "/mnt/space/miniconda3/envs/pygisbook/lib/python3.9/site-packages/jupyter_cache/executors/utils.py", line 51, in single_nb_execution
    executenb(
  File "/mnt/space/miniconda3/envs/pygisbook/lib/python3.9/site-packages/nbclient/client.py", line 1204, in execute
    return NotebookClient(nb=nb, resources=resources, km=km, **kwargs).execute()
  File "/mnt/space/miniconda3/envs/pygisbook/lib/python3.9/site-packages/nbclient/util.py", line 84, in wrapped
    return just_run(coro(*args, **kwargs))
  File "/mnt/space/miniconda3/envs/pygisbook/lib/python3.9/site-packages/nbclient/util.py", line 62, in just_run
    return loop.run_until_complete(coro)
  File "/mnt/space/miniconda3/envs/pygisbook/lib/python3.9/asyncio/base_events.py", line 647, in run_until_complete
    return future.result()
  File "/mnt/space/miniconda3/envs/pygisbook/lib/python3.9/site-packages/nbclient/client.py", line 663, in async_execute
    await self.async_execute_cell(
  File "/mnt/space/miniconda3/envs/pygisbook/lib/python3.9/site-packages/nbclient/client.py", line 965, in async_execute_cell
    await self._check_raise_for_error(cell, cell_index, exec_reply)
  File "/mnt/space/miniconda3/envs/pygisbook/lib/python3.9/site-packages/nbclient/client.py", line 862, in _check_raise_for_error
    raise CellExecutionError.from_cell_and_msg(cell, exec_reply_content)
nbclient.exceptions.CellExecutionError: An error occurred while executing the following cell:
------------------
import geopandas
import contextily as ctx
cities = geopandas.read_file(geopandas.datasets.get_path('naturalearth_cities'))
cities = cities[cities.name == 'Washington, D.C.']
cities = cities.to_crs(epsg=3857) # project to webmercator

ax = cities.plot(figsize=(10, 10), alpha=0.5, edgecolor='k')
ctx.add_basemap(ax, source=ctx.providers.CartoDB.Positron,zoom = 6, reset_extent = True)
------------------

[0;31m---------------------------------------------------------------------------[0m
[0;31mModuleNotFoundError[0m                       Traceback (most recent call last)
Cell [0;32mIn [1], line 2[0m
[1;32m      1[0m [38;5;28;01mimport[39;00m [38;5;21;01mgeopandas[39;00m
[0;32m----> 2[0m [38;5;28;01mimport[39;00m [38;5;21;01mcontextily[39;00m [38;5;28;01mas[39;00m [38;5;21;01mctx[39;00m
[1;32m      3[0m cities [38;5;241m=[39m geopandas[38;5;241m.[39mread_file(geopandas[38;5;241m.[39mdatasets[38;5;241m.[39mget_path([38;5;124m'[39m[38;5;124mnaturalearth_cities[39m[38;5;124m'[39m))
[1;32m      4[0m cities [38;5;241m=[39m cities[cities[38;5;241m.[39mname [38;5;241m==[39m [38;5;124m'[39m[38;5;124mWashington, D.C.[39m[38;5;124m'[39m]

[0;31mModuleNotFoundError[0m: No module named 'contextily'
ModuleNotFoundError: No module named 'contextily'

