Traceback (most recent call last):
  File "/mnt/space/miniconda3/envs/pygisbook/lib/python3.9/site-packages/jupyter_cache/executors/utils.py", line 51, in single_nb_execution
    executenb(
  File "/mnt/space/miniconda3/envs/pygisbook/lib/python3.9/site-packages/nbclient/client.py", line 1204, in execute
    return NotebookClient(nb=nb, resources=resources, km=km, **kwargs).execute()
  File "/mnt/space/miniconda3/envs/pygisbook/lib/python3.9/site-packages/nbclient/util.py", line 84, in wrapped
    return just_run(coro(*args, **kwargs))
  File "/mnt/space/miniconda3/envs/pygisbook/lib/python3.9/site-packages/nbclient/util.py", line 62, in just_run
    return loop.run_until_complete(coro)
  File "/mnt/space/miniconda3/envs/pygisbook/lib/python3.9/asyncio/base_events.py", line 647, in run_until_complete
    return future.result()
  File "/mnt/space/miniconda3/envs/pygisbook/lib/python3.9/site-packages/nbclient/client.py", line 663, in async_execute
    await self.async_execute_cell(
  File "/mnt/space/miniconda3/envs/pygisbook/lib/python3.9/site-packages/nbclient/client.py", line 965, in async_execute_cell
    await self._check_raise_for_error(cell, cell_index, exec_reply)
  File "/mnt/space/miniconda3/envs/pygisbook/lib/python3.9/site-packages/nbclient/client.py", line 862, in _check_raise_for_error
    raise CellExecutionError.from_cell_and_msg(cell, exec_reply_content)
nbclient.exceptions.CellExecutionError: An error occurred while executing the following cell:
------------------
import geowombat as gw
import matplotlib.pyplot as plt

fig, ax = plt.subplots(dpi=200)

# tell gw to read a blue green red
with gw.config.update(sensor="bgr"):
    with gw.open("../data/LC08_L1TP_224078_20200518_20200518_01_RT.TIF") as src:
        
        # see that bands names, blue green red are assigned
        print(src.band)

        # remove 0 value, rearrange band order 
        temp = src.where(src != 0).sel(band=["red", "green", "blue"])

        # plot
        temp.gw.imshow(robust=True, ax=ax)

        #save to file
        temp.gw.save(
            "../temp/LS_scaled_20200518.tif",  n_workers=4, overwrite=True
        )
------------------

[0;31m---------------------------------------------------------------------------[0m
[0;31mTypeError[0m                                 Traceback (most recent call last)
Cell [0;32mIn [15], line 20[0m
[1;32m     17[0m temp[38;5;241m.[39mgw[38;5;241m.[39mimshow(robust[38;5;241m=[39m[38;5;28;01mTrue[39;00m, ax[38;5;241m=[39max)
[1;32m     19[0m [38;5;66;03m#save to file[39;00m
[0;32m---> 20[0m temp[38;5;241m.[39mgw[38;5;241m.[39msave(
[1;32m     21[0m     [38;5;124m"[39m[38;5;124m../temp/LS_scaled_20200518.tif[39m[38;5;124m"[39m,  n_workers[38;5;241m=[39m[38;5;241m4[39m, overwrite[38;5;241m=[39m[38;5;28;01mTrue[39;00m
[1;32m     22[0m )

[0;31mTypeError[0m: save() got an unexpected keyword argument 'n_workers'
TypeError: save() got an unexpected keyword argument 'n_workers'

