Traceback (most recent call last):
  File "/home/mmann1123/anaconda3/envs/pygisbookgw/lib/python3.7/site-packages/jupyter_cache/executors/utils.py", line 56, in single_nb_execution
    record_timing=False,
  File "/home/mmann1123/anaconda3/envs/pygisbookgw/lib/python3.7/site-packages/nbclient/client.py", line 1112, in execute
    return NotebookClient(nb=nb, resources=resources, km=km, **kwargs).execute()
  File "/home/mmann1123/anaconda3/envs/pygisbookgw/lib/python3.7/site-packages/nbclient/util.py", line 74, in wrapped
    return just_run(coro(*args, **kwargs))
  File "/home/mmann1123/anaconda3/envs/pygisbookgw/lib/python3.7/site-packages/nbclient/util.py", line 53, in just_run
    return loop.run_until_complete(coro)
  File "/home/mmann1123/anaconda3/envs/pygisbookgw/lib/python3.7/asyncio/base_events.py", line 587, in run_until_complete
    return future.result()
  File "/home/mmann1123/anaconda3/envs/pygisbookgw/lib/python3.7/site-packages/nbclient/client.py", line 554, in async_execute
    cell, index, execution_count=self.code_cells_executed + 1
  File "/home/mmann1123/anaconda3/envs/pygisbookgw/lib/python3.7/site-packages/nbclient/client.py", line 857, in async_execute_cell
    self._check_raise_for_error(cell, exec_reply)
  File "/home/mmann1123/anaconda3/envs/pygisbookgw/lib/python3.7/site-packages/nbclient/client.py", line 760, in _check_raise_for_error
    raise CellExecutionError.from_cell_and_msg(cell, exec_reply_content)
nbclient.exceptions.CellExecutionError: An error occurred while executing the following cell:
------------------
dst_crs = "EPSG:3857"  # web mercator(ie google maps)

with rasterio.open("../data/LC08_L1TP_224078_20200518_20200518_01_RT.TIF") as src:
    src_transform = src.transform

    # calculate the transform matrix for the output
    dst_transform, width, height = calculate_default_transform(
        src.crs,
        dst_crs,
        src.width,
        src.height,
        *src.bounds,  # unpacks outer boundaries (left, bottom, right, top)
    )

    # set properties for output
    dst_kwargs = src.meta.copy()
    dst_kwargs.update(
        {
            "crs": dst_crs,
            "transform": dst_transform,
            "width": width,
            "height": height,
            "nodata": 0,  # replace 0 with np.nan
        }
    )

    with rasterio.open("../temp/LC08_20200518_webMC.tif", "w", **dst_kwargs) as dst:
        # iterate through bands
        for i in range(1, src.count + 1):
            array.reproject(
                source=rasterio.band(src, i),
                destination=rasterio.band(dst, i),
                src_transform=src.transform,
                src_crs=src.crs,
                dst_transform=dst_transform,
                dst_crs=dst_crs,
                resampling=Resampling.nearest,
            )
------------------

[0;31m---------------------------------------------------------------------------[0m
[0;31mNameError[0m                                 Traceback (most recent call last)
[0;32m<ipython-input-4-ae2c7f0d50d3>[0m in [0;36m<module>[0;34m[0m
[1;32m     28[0m         [0;31m# iterate through bands[0m[0;34m[0m[0;34m[0m[0;34m[0m[0m
[1;32m     29[0m         [0;32mfor[0m [0mi[0m [0;32min[0m [0mrange[0m[0;34m([0m[0;36m1[0m[0;34m,[0m [0msrc[0m[0;34m.[0m[0mcount[0m [0;34m+[0m [0;36m1[0m[0;34m)[0m[0;34m:[0m[0;34m[0m[0;34m[0m[0m
[0;32m---> 30[0;31m             array.reproject(
[0m[1;32m     31[0m                 [0msource[0m[0;34m=[0m[0mrasterio[0m[0;34m.[0m[0mband[0m[0;34m([0m[0msrc[0m[0;34m,[0m [0mi[0m[0;34m)[0m[0;34m,[0m[0;34m[0m[0;34m[0m[0m
[1;32m     32[0m                 [0mdestination[0m[0;34m=[0m[0mrasterio[0m[0;34m.[0m[0mband[0m[0;34m([0m[0mdst[0m[0;34m,[0m [0mi[0m[0;34m)[0m[0;34m,[0m[0;34m[0m[0;34m[0m[0m

[0;31mNameError[0m: name 'array' is not defined
NameError: name 'array' is not defined

