Traceback (most recent call last):
  File "/mnt/space/miniconda3/envs/pygisbook/lib/python3.9/site-packages/jupyter_cache/executors/utils.py", line 51, in single_nb_execution
    executenb(
  File "/mnt/space/miniconda3/envs/pygisbook/lib/python3.9/site-packages/nbclient/client.py", line 1204, in execute
    return NotebookClient(nb=nb, resources=resources, km=km, **kwargs).execute()
  File "/mnt/space/miniconda3/envs/pygisbook/lib/python3.9/site-packages/nbclient/util.py", line 84, in wrapped
    return just_run(coro(*args, **kwargs))
  File "/mnt/space/miniconda3/envs/pygisbook/lib/python3.9/site-packages/nbclient/util.py", line 62, in just_run
    return loop.run_until_complete(coro)
  File "/mnt/space/miniconda3/envs/pygisbook/lib/python3.9/asyncio/base_events.py", line 647, in run_until_complete
    return future.result()
  File "/mnt/space/miniconda3/envs/pygisbook/lib/python3.9/site-packages/nbclient/client.py", line 663, in async_execute
    await self.async_execute_cell(
  File "/mnt/space/miniconda3/envs/pygisbook/lib/python3.9/site-packages/nbclient/client.py", line 965, in async_execute_cell
    await self._check_raise_for_error(cell, cell_index, exec_reply)
  File "/mnt/space/miniconda3/envs/pygisbook/lib/python3.9/site-packages/nbclient/client.py", line 862, in _check_raise_for_error
    raise CellExecutionError.from_cell_and_msg(cell, exec_reply_content)
nbclient.exceptions.CellExecutionError: An error occurred while executing the following cell:
------------------
import geowombat as gw

proj4 = "+proj=aea +lat_1=20 +lat_2=60 +lat_0=40 +lon_0=-96 +x_0=0 +y_0=0 +datum=NAD83 +units=m +no_defs"
image = "../data/LC08_L1TP_224078_20200518_20200518_01_RT.TIF"

with gw.config.update(ref_crs=proj4):
    with gw.open(image, resampling="nearest") as src:
    
        src.gw.save(
            "../temp/LC08_20200518_aea.tif",
            n_workers=4,  # number of process workers 
            overwrite=True,
        ) 
------------------

[0;31m---------------------------------------------------------------------------[0m
[0;31mTypeError[0m                                 Traceback (most recent call last)
Cell [0;32mIn [1], line 9[0m
[1;32m      6[0m [38;5;28;01mwith[39;00m gw[38;5;241m.[39mconfig[38;5;241m.[39mupdate(ref_crs[38;5;241m=[39mproj4):
[1;32m      7[0m     [38;5;28;01mwith[39;00m gw[38;5;241m.[39mopen(image, resampling[38;5;241m=[39m[38;5;124m"[39m[38;5;124mnearest[39m[38;5;124m"[39m) [38;5;28;01mas[39;00m src:
[0;32m----> 9[0m         src[38;5;241m.[39mgw[38;5;241m.[39msave(
[1;32m     10[0m             [38;5;124m"[39m[38;5;124m../temp/LC08_20200518_aea.tif[39m[38;5;124m"[39m,
[1;32m     11[0m             n_workers[38;5;241m=[39m[38;5;241m4[39m,  [38;5;66;03m# number of process workers [39;00m
[1;32m     12[0m             overwrite[38;5;241m=[39m[38;5;28;01mTrue[39;00m,
[1;32m     13[0m         )

[0;31mTypeError[0m: save() got an unexpected keyword argument 'n_workers'
TypeError: save() got an unexpected keyword argument 'n_workers'

