Traceback (most recent call last):
  File "/home/mmann1123/anaconda3/envs/pygisbookgw/lib/python3.7/site-packages/jupyter_cache/executors/utils.py", line 56, in single_nb_execution
    record_timing=False,
  File "/home/mmann1123/anaconda3/envs/pygisbookgw/lib/python3.7/site-packages/nbclient/client.py", line 1112, in execute
    return NotebookClient(nb=nb, resources=resources, km=km, **kwargs).execute()
  File "/home/mmann1123/anaconda3/envs/pygisbookgw/lib/python3.7/site-packages/nbclient/util.py", line 74, in wrapped
    return just_run(coro(*args, **kwargs))
  File "/home/mmann1123/anaconda3/envs/pygisbookgw/lib/python3.7/site-packages/nbclient/util.py", line 53, in just_run
    return loop.run_until_complete(coro)
  File "/home/mmann1123/anaconda3/envs/pygisbookgw/lib/python3.7/asyncio/base_events.py", line 587, in run_until_complete
    return future.result()
  File "/home/mmann1123/anaconda3/envs/pygisbookgw/lib/python3.7/site-packages/nbclient/client.py", line 554, in async_execute
    cell, index, execution_count=self.code_cells_executed + 1
  File "/home/mmann1123/anaconda3/envs/pygisbookgw/lib/python3.7/site-packages/nbclient/client.py", line 857, in async_execute_cell
    self._check_raise_for_error(cell, exec_reply)
  File "/home/mmann1123/anaconda3/envs/pygisbookgw/lib/python3.7/site-packages/nbclient/client.py", line 760, in _check_raise_for_error
    raise CellExecutionError.from_cell_and_msg(cell, exec_reply_content)
nbclient.exceptions.CellExecutionError: An error occurred while executing the following cell:
------------------
fig, ax = plt.subplots(dpi=150)

with gw.config.update(sensor='qb', scale_factor=0.0001):
    with gw.open(rgbn) as ds:
        tcap = ds.gw.tasseled_cap()
        tcap.sel(band='wetness').plot(robust=True, ax=ax)
        print(tcap)
plt.tight_layout(pad=1)

------------------

[0;31m---------------------------------------------------------------------------[0m
[0;31mTypeError[0m                                 Traceback (most recent call last)
[0;32m<ipython-input-6-376be95b7ba3>[0m in [0;36m<module>[0;34m[0m
[1;32m      4[0m     [0;32mwith[0m [0mgw[0m[0;34m.[0m[0mopen[0m[0;34m([0m[0mrgbn[0m[0;34m)[0m [0;32mas[0m [0mds[0m[0;34m:[0m[0;34m[0m[0;34m[0m[0m
[1;32m      5[0m         [0mtcap[0m [0;34m=[0m [0mds[0m[0;34m.[0m[0mgw[0m[0;34m.[0m[0mtasseled_cap[0m[0;34m([0m[0;34m)[0m[0;34m[0m[0;34m[0m[0m
[0;32m----> 6[0;31m         [0mtcap[0m[0;34m.[0m[0msel[0m[0;34m([0m[0mband[0m[0;34m=[0m[0;34m'wetness'[0m[0;34m)[0m[0;34m.[0m[0mplot[0m[0;34m([0m[0mrobust[0m[0;34m=[0m[0;32mTrue[0m[0;34m,[0m [0max[0m[0;34m=[0m[0max[0m[0;34m)[0m[0;34m[0m[0;34m[0m[0m
[0m[1;32m      7[0m         [0mprint[0m[0;34m([0m[0mtcap[0m[0;34m)[0m[0;34m[0m[0;34m[0m[0m
[1;32m      8[0m [0mplt[0m[0;34m.[0m[0mtight_layout[0m[0;34m([0m[0mpad[0m[0;34m=[0m[0;36m1[0m[0;34m)[0m[0;34m[0m[0;34m[0m[0m

[0;32m~/anaconda3/envs/pygisbookgw/lib/python3.7/site-packages/xarray/plot/plot.py[0m in [0;36m__call__[0;34m(self, **kwargs)[0m
[1;32m    442[0m [0;34m[0m[0m
[1;32m    443[0m     [0;32mdef[0m [0m__call__[0m[0;34m([0m[0mself[0m[0;34m,[0m [0;34m**[0m[0mkwargs[0m[0;34m)[0m[0;34m:[0m[0;34m[0m[0;34m[0m[0m
[0;32m--> 444[0;31m         [0;32mreturn[0m [0mplot[0m[0;34m([0m[0mself[0m[0;34m.[0m[0m_da[0m[0;34m,[0m [0;34m**[0m[0mkwargs[0m[0;34m)[0m[0;34m[0m[0;34m[0m[0m
[0m[1;32m    445[0m [0;34m[0m[0m
[1;32m    446[0m     [0;31m# we can't use functools.wraps here since that also modifies the name / qualname[0m[0;34m[0m[0;34m[0m[0;34m[0m[0m

[0;32m~/anaconda3/envs/pygisbookgw/lib/python3.7/site-packages/xarray/plot/plot.py[0m in [0;36mplot[0;34m(darray, row, col, col_wrap, ax, hue, rtol, subplot_kws, **kwargs)[0m
[1;32m    195[0m     [0mkwargs[0m[0;34m[[0m[0;34m"ax"[0m[0;34m][0m [0;34m=[0m [0max[0m[0;34m[0m[0;34m[0m[0m
[1;32m    196[0m [0;34m[0m[0m
[0;32m--> 197[0;31m     [0;32mreturn[0m [0mplotfunc[0m[0;34m([0m[0mdarray[0m[0;34m,[0m [0;34m**[0m[0mkwargs[0m[0;34m)[0m[0;34m[0m[0;34m[0m[0m
[0m[1;32m    198[0m [0;34m[0m[0m
[1;32m    199[0m [0;34m[0m[0m

[0;32m~/anaconda3/envs/pygisbookgw/lib/python3.7/site-packages/xarray/plot/plot.py[0m in [0;36mnewplotfunc[0;34m(darray, x, y, figsize, size, aspect, ax, row, col, col_wrap, xincrease, yincrease, add_colorbar, add_labels, vmin, vmax, cmap, center, robust, extend, levels, infer_intervals, colors, subplot_kws, cbar_ax, cbar_kwargs, xscale, yscale, xticks, yticks, xlim, ylim, norm, **kwargs)[0m
[1;32m    712[0m         [0myplt[0m[0;34m,[0m [0mylab_extra[0m [0;34m=[0m [0m_resolve_intervals_2dplot[0m[0;34m([0m[0myval[0m[0;34m,[0m [0mplotfunc[0m[0;34m.[0m[0m__name__[0m[0;34m)[0m[0;34m[0m[0;34m[0m[0m
[1;32m    713[0m [0;34m[0m[0m
[0;32m--> 714[0;31m         [0m_ensure_plottable[0m[0;34m([0m[0mxplt[0m[0;34m,[0m [0myplt[0m[0;34m,[0m [0mzval[0m[0;34m)[0m[0;34m[0m[0;34m[0m[0m
[0m[1;32m    715[0m [0;34m[0m[0m
[1;32m    716[0m         cmap_params, cbar_kwargs = _process_cmap_cbar_kwargs(

[0;32m~/anaconda3/envs/pygisbookgw/lib/python3.7/site-packages/xarray/plot/utils.py[0m in [0;36m_ensure_plottable[0;34m(*args)[0m
[1;32m    604[0m         ):
[1;32m    605[0m             raise TypeError(
[0;32m--> 606[0;31m                 [0;34m"Plotting requires coordinates to be numeric, boolean, "[0m[0;34m[0m[0;34m[0m[0m
[0m[1;32m    607[0m                 [0;34m"or dates of type numpy.datetime64, "[0m[0;34m[0m[0;34m[0m[0m
[1;32m    608[0m                 [0;34m"datetime.datetime, cftime.datetime or "[0m[0;34m[0m[0;34m[0m[0m

[0;31mTypeError[0m: Plotting requires coordinates to be numeric, boolean, or dates of type numpy.datetime64, datetime.datetime, cftime.datetime or pandas.Interval. Received data of type object instead.
TypeError: Plotting requires coordinates to be numeric, boolean, or dates of type numpy.datetime64, datetime.datetime, cftime.datetime or pandas.Interval. Received data of type object instead.

